Workbook

Sheet الباقات
A1: الباقة | B1: لمن | C1: الإجمالي $ | D1: منه بأسعار منشورة $ | E1: النسبة
A2: الباقة الأساسية | B2: ورشة ناشئة بفنيَّين، تحوّل سيارة واحدة شهرياً. | C2: =البنود!L59 | D2: =SUMIFS(البنود!L2:L57,البنود!F2:F57,"<>تقدير") | E2: =D2/C2
A3: الباقة المتوسطة | B3: ورشة منتظمة تحوّل سيارتين إلى ثلاث شهرياً. | C3: =البنود!M59 | D3: =SUMIFS(البنود!M2:M57,البنود!F2:F57,"<>تقدير") | E3: =D3/C3
A4: الباقة الاحترافية | B4: مركز تحويل معتمد بثلاثة فنيين أو أكثر. | C4: =البنود!N59 | D4: =SUMIFS(البنود!N2:N57,البنود!F2:F57,"<>تقدير") | E4: =D4/C4
A6: ملاحظة | B6: الأسعار بالدولار في 25/10/2026 دون الشحن والجمارك. اليورو 1.15، والجنيه 1.30، والروبية 84 لكل دولار. غيّر الكميات في ورقة البنود فتتحدث الإجماليات.

Sheet البنود
A1: المجموعة | B1: البند | C1: المنطقة | D1: الخيار | E1: الفئة | F1: نوع السعر | G1: السعر الأصلي | H1: سعر الوحدة $ | I1: كمية أ | J1: كمية م | K1: كمية ح | L1: إجمالي أ | M1: إجمالي م | N1: إجمالي ح | O1: المصدر | P1: الرابط
A2: الرفع وفك منظومة الاحتراق | B2: رافعة سيارات بعمودين 4 طن | C2: Z1 منصة الرفع | D2: رافعة صينية 4,000 كغ (Qingdao Gaosheng Huitong) | E2: اقتصادي | F2: نطاق المصنع | G2: $999–1,299 FOB | H2: 1299 | I2: 1 | J2: 1 | K2: 0 | L2: =H2*I2 | M2: =H2*J2 | N2: =H2*K2 | O2: Made-in-China · رافعات بعمودين 4,000 كغ (Qingdao Gaosheng Huitong) | P2: https://m.made-in-china.com/catlist/Car-Lift-2901010000.html
A3: الرفع وفك منظومة الاحتراق | B3: رافعة سيارات بعمودين 4 طن | C3: Z1 منصة الرفع | D3: BendPak 10APX · 10,000 lb · معتمدة ALI | E3: علامة معروفة | F3: سعر منشور | G3: $6,895 | H3: 6895 | I3: 0 | J3: 0 | K3: 1 | L3: =H3*I3 | M3: =H3*J3 | N3: =H3*K3 | O3: Obsessed Garage · BendPak 10APX | P3: https://www.obsessedgarage.com/products/bendpak-10apx-two-post-lift
A4: الرفع وفك منظومة الاحتراق | B4: رافعة محرك قابلة للطي 2 طن | C4: Z2 فك المحرك والسوائل | D4: Pittsburgh 2-Ton Foldable Shop Crane 58755 | E4: علامة معروفة | F4: سعر منشور | G4: $369.99 | H4: 369.99 | I4: 1 | J4: 1 | K4: 1 | L4: =H4*I4 | M4: =H4*J4 | N4: =H4*K4 | O4: Front Desk Review · Pittsburgh 2-Ton Foldable Crane 58755 (سعر Harbor Freight في 10/10/2026) | P4: https://frontdeskreview.com/product/engine-hoists/pittsburgh-automotive-58755/
A5: الرفع وفك منظومة الاحتراق | B5: معدّل ميل المحرك | C5: Z2 فك المحرك والسوائل | D5: Pittsburgh 2 Ton Load Leveler 60659 | E5: علامة معروفة | F5: سعر منشور | G5: $44.99 | H5: 44.99 | I5: 1 | J5: 1 | K5: 1 | L5: =H5*I5 | M5: =H5*J5 | N5: =H5*K5 | O5: Harbor Freight · 2 Ton Load Leveler 60659 | P5: https://www.harborfreight.com/2-ton-capacity-heavy-duty-load-leveler-60659.html
A6: الرفع وفك منظومة الاحتراق | B6: رافعة ناقل حركة منخفضة | C6: Z1 منصة الرفع | D6: Pittsburgh 450 lb Low-Lift Transmission Jack | E6: علامة معروفة | F6: سعر منشور | G6: $129.99 | H6: 129.99 | I6: 1 | J6: 0 | K6: 0 | L6: =H6*I6 | M6: =H6*J6 | N6: =H6*K6 | O6: Harbor Freight · Transmission Jacks | P6: https://www.harborfreight.com/automotive/jacks-jack-stands/transmission-jacks.html
A7: الرفع وفك منظومة الاحتراق | B7: رافعة ناقل حركة منخفضة | C7: Z1 منصة الرفع | D7: Pittsburgh 800 lb Low-Lift Transmission Jack | E7: علامة معروفة | F7: سعر منشور | G7: $239.99 | H7: 239.99 | I7: 0 | J7: 1 | K7: 1 | L7: =H7*I7 | M7: =H7*J7 | N7: =H7*K7 | O7: Harbor Freight · Transmission Jacks | P7: https://www.harborfreight.com/automotive/jacks-jack-stands/transmission-jacks.html
A8: الرفع وفك منظومة الاحتراق | B8: طاولة رفع البطارية | C8: Z1 منصة الرفع | D8: طاولة صينية لبطاريات EV · 1,500 كغ (Hongtech / ZeHoo) | E8: اقتصادي | F8: نطاق المصنع | G8: $870–1,070 | H8: 980 | I8: 0 | J8: 1 | K8: 0 | L8: =H8*I8 | M8: =H8*J8 | N8: =H8*K8 | O8: Accio (Alibaba) · طاولات رفع بطاريات EV | P8: https://www.accio.ai/find-product/scissor-lift-battery-price
A9: الرفع وفك منظومة الاحتراق | B9: طاولة رفع البطارية | C9: Z1 منصة الرفع | D9: Big Red Torin ATDP10001R · 1 طن | E9: علامة معروفة | F9: سعر منشور | G9: $2,429.99 | H9: 2429.99 | I9: 0 | J9: 0 | K9: 1 | L9: =H9*I9 | M9: =H9*J9 | N9: =H9*K9 | O9: Slickdeals · Big Red Torin ATDP10001R (Amazon) | P9: https://slickdeals.net/f/19913265-big-red-atdp10001r-torin-1-ton-battery-lift-table-hydraulic-platform-for-safe-ev-hybrid-battery-removal-repair-insulated-adjustable-tray-dual-cylinder-2429-99
A10: الرفع وفك منظومة الاحتراق | B10: طاولة رفع البطارية | C10: Z1 منصة الرفع | D10: Laser Tools 8889 · 1.2 طن | E10: علامة معروفة | F10: سعر منشور | G10: £3,920 دون الضريبة | H10: 5096.04 | I10: 0 | J10: 0 | K10: 0 | L10: =H10*I10 | M10: =H10*J10 | N10: =H10*K10 | O10: Tool Connection · Laser Tools 8889 EV Battery Lifting Table | P10: https://www.toolconnection.co.uk/products/hybrid-electric-vehicles/workshop-equipment/lifting/8889-ev-battery-lifting-table-1-2-tonne
A11: الرفع وفك منظومة الاحتراق | B11: معدات تفريغ الوقود والزيوت والمبرد | C11: Z2 فك المحرك والسوائل | D11: طقم تفريغ عام (مضخة + حاوية + حوض) | E11: اقتصادي | F11: تقدير | H11: 150 | I11: 1 | J11: 1 | K11: 1 | L11: =H11*I11 | M11: =H11*J11 | N11: =H11*K11 | O11: تقدير
A12: الحماية الشخصية والسلامة من الجهد العالي | B12: قفازات عازلة فئة 0 مع واقيات جلدية | C12: Z7 محطة الحماية | D12: قفازات فئة 0 صينية | E12: اقتصادي | F12: تقدير | H12: 45 | I12: 0 | J12: 0 | K12: 0 | L12: =H12*I12 | M12: =H12*J12 | N12: =H12*K12 | O12: تقدير
A13: الحماية الشخصية والسلامة من الجهد العالي | B13: قفازات عازلة فئة 0 مع واقيات جلدية | C13: Z7 محطة الحماية | D13: Salisbury GK011Y · طقم القفاز والواقي والحقيبة | E13: علامة معروفة | F13: سعر منشور | G13: $190.99 | H13: 190.99 | I13: 2 | J13: 2 | K13: 3 | L13: =H13*I13 | M13: =H13*J13 | N13: =H13*K13 | O13: Zoro · Salisbury GK011Y Class 0 Glove Kit | P13: https://www.zoro.com/salisbury-electrical-insulating-glove-kit-1-000v-ac-1-500v-dc-rubber-11-length-yellow-size-9-gk011y9/i/G2051856/
A14: الحماية الشخصية والسلامة من الجهد العالي | B14: طقم أدوات معزولة 1,000 V | C14: Z7 محطة الحماية | D14: طقم صيني بعلامة VDE / IEC 60900 | E14: اقتصادي | F14: تقدير | H14: 95 | I14: 1 | J14: 0 | K14: 0 | L14: =H14*I14 | M14: =H14*J14 | N14: =H14*K14 | O14: تقدير
A15: الحماية الشخصية والسلامة من الجهد العالي | B15: طقم أدوات معزولة 1,000 V | C15: Z7 محطة الحماية | D15: Wiha 91890 · 26 قطعة للسيارات الهجينة والكهربائية | E15: علامة معروفة | F15: سعر منشور | G15: $519.98 | H15: 519.98 | I15: 0 | J15: 1 | K15: 2 | L15: =H15*I15 | M15: =H15*J15 | N15: =H15*K15 | O15: SupplyHouse · Wiha 91890 Insulated EV Kit | P15: https://www.supplyhouse.com/Wiha-91890-26-Piece-Insulated-Hybrid-and-EV-Essentials-Tool-Kit
A16: الحماية الشخصية والسلامة من الجهد العالي | B16: خطاف إنقاذ معزول | C16: Z1 منصة الرفع | D16: خطاف إنقاذ صيني من الألياف الزجاجية | E16: اقتصادي | F16: تقدير | H16: 60 | I16: 1 | J16: 2 | K16: 0 | L16: =H16*I16 | M16: =H16*J16 | N16: =H16*K16 | O16: تقدير
A17: الحماية الشخصية والسلامة من الجهد العالي | B17: خطاف إنقاذ معزول | C17: Z1 منصة الرفع | D17: Salisbury 24401 Insulated Rescue Hook | E17: علامة معروفة | F17: سعر منشور | G17: $548.38 | H17: 548.38 | I17: 0 | J17: 0 | K17: 2 | L17: =H17*I17 | M17: =H17*J17 | N17: =H17*K17 | O17: Stauffer Safety · Salisbury 24401 Rescue Hook | P17: https://www.stauffersafety.com/Brands/salisbury/Catalog/electrical-safety/accessories/salisbury-24401-es-insulated-rescue-hook-654968
A18: الحماية الشخصية والسلامة من الجهد العالي | B18: سجادة أرضية عازلة فئة 0 | C18: Z3 غرفة تجميع البطاريات | D18: سجادة مطاطية صينية فئة 0 | E18: اقتصادي | F18: تقدير | H18: 90 | I18: 1 | J18: 0 | K18: 0 | L18: =H18*I18 | M18: =H18*J18 | N18: =H18*K18 | O18: تقدير
A19: الحماية الشخصية والسلامة من الجهد العالي | B19: سجادة أرضية عازلة فئة 0 | C19: Z3 غرفة تجميع البطاريات | D19: RS PRO 0830152 · 1 × 3 م | E19: علامة معروفة | F19: سعر منشور | G19: £236.13 دون الضريبة | H19: 306.97 | I19: 0 | J19: 1 | K19: 2 | L19: =H19*I19 | M19: =H19*J19 | N19: =H19*K19 | O19: RS Components · RS PRO 0830152 Class 0 Mat 1 × 3 m | P19: https://uk.rs-online.com/web/p/electrical-safety-mats/0830152
A20: الحماية الشخصية والسلامة من الجهد العالي | B20: واقي وجه ضد القوس الكهربائي ونظارات وحذاء سلامة | C20: Z7 محطة الحماية | D20: طقم صيني لفني واحد | E20: اقتصادي | F20: تقدير | H20: 120 | I20: 2 | J20: 2 | K20: 0 | L20: =H20*I20 | M20: =H20*J20 | N20: =H20*K20 | O20: تقدير
A21: الحماية الشخصية والسلامة من الجهد العالي | B21: واقي وجه ضد القوس الكهربائي ونظارات وحذاء سلامة | C21: Z7 محطة الحماية | D21: طقم بعلامات معروفة لفني واحد | E21: علامة معروفة | F21: تقدير | H21: 450 | I21: 0 | J21: 0 | K21: 3 | L21: =H21*I21 | M21: =H21*J21 | N21: =H21*K21 | O21: تقدير
A22: الحماية الشخصية والسلامة من الجهد العالي | B22: طقم العزل والتعليم LOTO وحواجز الجهد العالي | C22: Z7 محطة الحماية | D22: طقم LOTO مع حواجز ولافتات | E22: اقتصادي | F22: تقدير | H22: 90 | I22: 1 | J22: 1 | K22: 2 | L22: =H22*I22 | M22: =H22*J22 | N22: =H22*K22 | O22: تقدير
A23: الحماية الشخصية والسلامة من الجهد العالي | B23: بطانية إطفاء للمركبات 6 × 8 م | C23: Z1 منصة الرفع | D23: بطانية صينية للمركبات 6 × 8 م | E23: اقتصادي | F23: تقدير | H23: 450 | I23: 1 | J23: 1 | K23: 0 | L23: =H23*I23 | M23: =H23*J23 | N23: =H23*K23 | O23: تقدير
A24: الحماية الشخصية والسلامة من الجهد العالي | B24: بطانية إطفاء للمركبات 6 × 8 م | C24: Z1 منصة الرفع | D24: Sealey EV1000 · مغطاة بالبولي يوريثان | E24: علامة معروفة | F24: سعر منشور | G24: £1,955.44 دون الضريبة | H24: 2542.07 | I24: 0 | J24: 0 | K24: 1 | L24: =H24*I24 | M24: =H24*J24 | N24: =H24*K24 | O24: Rapid Electronics · Sealey EV1000 Fire Blanket 6 × 8 m | P24: https://www.rapidonline.com/sealey-ev1000-vehicle-fire-safety-blanket-pu-coated-6-x-8m-94-5873
A25: الحماية الشخصية والسلامة من الجهد العالي | B25: طفايات حريق ودلو رمل جاف | C25: Z3 غرفة تجميع البطاريات | D25: طقم الطفايات والرمل | E25: اقتصادي | F25: تقدير | H25: 180 | I25: 1 | J25: 2 | K25: 3 | L25: =H25*I25 | M25: =H25*J25 | N25: =H25*K25 | O25: تقدير
A26: القياس والتشخيص | B26: جهاز قياس مقاومة العزل | C26: Z5 القياس والبرمجة | D26: UNI-T UT502A · 500 / 1,000 / 2,500 V | E26: اقتصادي | F26: سعر منشور | G26: €92.13 دون الضريبة | H26: 105.95 | I26: 1 | J26: 0 | K26: 0 | L26: =H26*I26 | M26: =H26*J26 | N26: =H26*K26 | O26: Eleshop · UNI-T UT502A | P26: https://eleshop.eu/uni-t-ut502a.html
A27: القياس والتشخيص | B27: جهاز قياس مقاومة العزل | C27: Z5 القياس والبرمجة | D27: Fluke 1507 · 50–1,000 V | E27: علامة معروفة | F27: سعر منشور | G27: $763.59 (السعر الأصلي $919.99) | H27: 763.59 | I27: 0 | J27: 1 | K27: 1 | L27: =H27*I27 | M27: =H27*J27 | N27: =H27*K27 | O27: Transcat · Fluke 1507 | P27: https://www.transcat.com/fluke-1507-fluke-1507
A28: القياس والتشخيص | B28: ملتيميتر True RMS بفئة CAT III 1,000 V | C28: Z5 القياس والبرمجة | D28: UNI-T UT61E+ · CAT III 1,000 V | E28: اقتصادي | F28: سعر منشور | G28: $103.39 + $40 شحن | H28: 103.39 | I28: 2 | J28: 0 | K28: 0 | L28: =H28*I28 | M28: =H28*J28 | N28: =H28*K28 | O28: eBay · UNI-T UT61E+ | P28: https://www.ebay.com/itm/286809229792
A29: القياس والتشخيص | B29: ملتيميتر True RMS بفئة CAT III 1,000 V | C29: Z5 القياس والبرمجة | D29: Fluke 87V | E29: علامة معروفة | F29: سعر منشور | G29: $318.62 (عرض 06/2023) | H29: 318.62 | I29: 0 | J29: 2 | K29: 2 | L29: =H29*I29 | M29: =H29*J29 | N29: =H29*K29 | O29: Slickdeals · Fluke 87V (Lowe's، 06/2023) | P29: https://slickdeals.net/f/16748897-fluke-87v-electrician-s-industrial-10a-1000v-digital-multimeter-318-60-free-shipping
A30: القياس والتشخيص | B30: ملقط تيار مستمر DC | C30: Z5 القياس والبرمجة | D30: UNI-T UT219DS · 600 A DC | E30: اقتصادي | F30: سعر منشور | G30: €103.20 دون الضريبة | H30: 118.68 | I30: 1 | J30: 1 | K30: 0 | L30: =H30*I30 | M30: =H30*J30 | N30: =H30*K30 | O30: Eleshop · UNI-T UT219DS | P30: https://eleshop.eu/uni-t-ut219ds-current-clamp.html
A31: القياس والتشخيص | B31: ملقط تيار مستمر DC | C31: Z5 القياس والبرمجة | D31: Fluke 376 FC · 999.9 A DC | E31: علامة معروفة | F31: سعر منشور | G31: $831.24 | H31: 831.24 | I31: 0 | J31: 0 | K31: 1 | L31: =H31*I31 | M31: =H31*J31 | N31: =H31*K31 | O31: Elliott Electric · Fluke 376 FC | P31: https://elliottelectric.com/P/Item/FLU/376FC/
A32: القياس والتشخيص | B32: كاشف جهد ثنائي القطب | C32: Z5 القياس والبرمجة | D32: كاشف جهد صيني ثنائي القطب | E32: اقتصادي | F32: تقدير | H32: 40 | I32: 1 | J32: 0 | K32: 0 | L32: =H32*I32 | M32: =H32*J32 | N32: =H32*K32 | O32: تقدير
A33: القياس والتشخيص | B33: كاشف جهد ثنائي القطب | C33: Z5 القياس والبرمجة | D33: كاشف بعلامة معروفة (فئة Fluke T6) | E33: علامة معروفة | F33: تقدير | H33: 260 | I33: 0 | J33: 1 | K33: 2 | L33: =H33*I33 | M33: =H33*J33 | N33: =H33*K33 | O33: تقدير
A34: القياس والتشخيص | B34: محلل شبكة CAN عبر USB | C34: Z5 القياس والبرمجة | D34: MKS CANable V2.0 · CAN FD | E34: اقتصادي | F34: سعر منشور | G34: ₹3,899 | H34: 46.42 | I34: 1 | J34: 0 | K34: 0 | L34: =H34*I34 | M34: =H34*J34 | N34: =H34*K34 | O34: Probots · MKS CANable V2.0 | P34: https://probots.co.in/mks-canable-v2-0-usb-to-can-analyzer-can-fd-stm32g431c8.html
A35: القياس والتشخيص | B35: محلل شبكة CAN عبر USB | C35: Z5 القياس والبرمجة | D35: PEAK PCAN-USB معزول ضوئياً · IPEH-002022 | E35: علامة معروفة | F35: سعر منشور | G35: $314 | H35: 314 | I35: 0 | J35: 1 | K35: 1 | L35: =H35*I35 | M35: =H35*J35 | N35: =H35*K35 | O35: Grid Connect · PEAK PCAN-USB opto-decoupled IPEH-002022 | P35: https://gridconnect.com/products/can-usb-adapter-pcan-usb
A36: القياس والتشخيص | B36: كاميرا حرارية | C36: Z5 القياس والبرمجة | D36: InfiRay P2 Pro · تتصل بالهاتف | E36: اقتصادي | F36: سعر منشور | G36: $299 (السعر الأصلي) | H36: 299 | I36: 0 | J36: 1 | K36: 0 | L36: =H36*I36 | M36: =H36*J36 | N36: =H36*K36 | O36: Android Central · InfiRay P2 Pro | P36: https://androidcentral.com/accessories/this-usb-c-thermal-camera-lets-you-see-your-surroundings-in-a-new-light-and-its-down-to-dollar219
A37: القياس والتشخيص | B37: كاميرا حرارية | C37: Z5 القياس والبرمجة | D37: كاميرا محمولة احترافية بعلامة معروفة | E37: علامة معروفة | F37: تقدير | H37: 1200 | I37: 0 | J37: 0 | K37: 1 | L37: =H37*I37 | M37: =H37*J37 | N37: =H37*K37 | O37: تقدير
A38: تجميع كتل البطارية | B38: جهاز قياس المقاومة الداخلية للخلايا | C38: Z3 غرفة تجميع البطاريات | D38: YR1035+ · 0–100 V · 0–200 Ω | E38: اقتصادي | F38: سعر منشور | G38: $99 | H38: 99 | I38: 1 | J38: 1 | K38: 0 | L38: =H38*I38 | M38: =H38*J38 | N38: =H38*K38 | O38: Fruugo · YR1035+ Internal Resistance Tester | P38: https://www.fruugo.ca/high-accuracy-fast-yr1035-lithium-battery-internal-resistance-test-instrument-100v-electric-vehicle-group-lithium-battery/p-420601047
A39: تجميع كتل البطارية | B39: جهاز قياس المقاومة الداخلية للخلايا | C39: Z3 غرفة تجميع البطاريات | D39: جهاز مخبري بعلامة معروفة (فئة Hioki BT3554) | E39: علامة معروفة | F39: تقدير | H39: 2000 | I39: 0 | J39: 0 | K39: 1 | L39: =H39*I39 | M39: =H39*J39 | N39: =H39*K39 | O39: تقدير
A40: تجميع كتل البطارية | B40: مزود طاقة لموازنة الخلايا | C40: Z3 غرفة تجميع البطاريات | D40: RIDEN RD6024 · 60 V / 24 A | E40: اقتصادي | F40: سعر منشور | G40: €103.61 + €31 شحن | H40: 119.15 | I40: 1 | J40: 2 | K40: 0 | L40: =H40*I40 | M40: =H40*J40 | N40: =H40*K40 | O40: eBay · RIDEN RD6024 | P40: https://www.ebay.de/itm/156181940601
...
